<?xml version="1.0"?>
<robot xmlns:xacro="http://ros.org/wiki/xacro"
       xmlns:gazebo="http://www.gazebosim.org/schema/gazebo_urdf"
       name="diffbot">

  <!-- ======================= -->
  <!-- === Propiedades === -->
  <!-- ======================= -->

  <xacro:property name="chassis_mass" value="0.8"/>
  <xacro:property name="wheel_radius" value="0.035"/>
  <xacro:property name="wheel_width" value="0.025"/>
  <xacro:property name="wheel_separation" value="0.16"/>
  <xacro:property name="wheel_color" value="silver"/>
  <xacro:property name="caster_origin_xyz" value="-0.075 0 0.002"/>
  <xacro:property name="caster_color" value="orange"/>

  <!-- ======================= -->
  <!-- === Includes === -->
  <!-- ======================= -->

  <xacro:include filename="$(find tp1_robot)/urdf/inertial_macros.xacro"/>
  <xacro:include filename="$(find tp1_robot)/urdf/motor.xacro"/>

  <!-- ======================= -->
  <!-- === Chasis del robot === -->
  <!-- ======================= -->

  <link name="base_link">
    <visual>
      <!-- <origin xyz="0 0 0" rpy="0 0 0"/>-->
      <geometry>
        <mesh filename="file://$(find tp1_robot)/meshes/chassis.stl"/>
      </geometry>
    </visual>
    <collision>
      <!-- <origin xyz="0 0 0" rpy="0 0 0"/>-->
      <geometry>
        <box size="0.195 0.1 0.05"/>
      </geometry>
    </collision>
    <xacro:inertial_box mass="${chassis_mass}" x="0.195" y="0.1" z="0.05"/>
  </link>

  <!-- ======================= -->
  <!-- === Macro para ruedas === -->
  <!-- ======================= -->

  <xacro:macro name="wheel" params="prefix xyz axis">
    <link name="${prefix}_wheel">
      <visual>
        <origin xyz="0 0 0" rpy="1.5708 0 0"/>
        <geometry>
          <cylinder radius="${wheel_radius}" length="${wheel_width}"/>
        </geometry>
        <material name="${wheel_color}"/>
      </visual>
      <collision>
        <origin xyz="0 0 0" rpy="1.5708 0 0"/>
        <geometry>
          <cylinder radius="${wheel_radius}" length="${wheel_width}"/>
        </geometry>
      </collision>
      <inertial>
        <mass value="0.2"/>
        <origin xyz="0 0 0" rpy="0 0 0"/>
        <inertia ixx="0.001" ixy="0.0" ixz="0.0"
                 iyy="0.001" iyz="0.0"
                 izz="0.001"/>
      </inertial>
    </link>

    <joint name="${prefix}_wheel_joint" type="continuous">
      <origin xyz="${xyz}" rpy="0 0 0"/>
      <parent link="base_link"/>
      <child link="${prefix}_wheel"/>
      <axis xyz="${axis}"/>
      <limit effort="10.0" velocity="10.0"/>
      <dynamics damping="0.1"/>
    </joint>

    <!-- Gazebo settings -->
    <gazebo reference="${prefix}_wheel">
      <mu1>1.0</mu1>
      <mu2>1.0</mu2>
      <material>Gazebo/Grey</material>
    </gazebo>
  </xacro:macro>

  <!-- ======================= -->
  <!-- === Ruedas y motores === -->
  <!-- ======================= -->

  <xacro:wheel prefix="left"  xyz="0.0175  0.065 -0.0175" axis="0 1 0"/>
  <xacro:wheel prefix="right" xyz="0.0175 -0.065 -0.0175" axis="0 1 0"/>
  <xacro:motor prefix="left" chassis_width="0.1" reflect="false"/>
  <xacro:motor prefix="right" chassis_width="0.1" reflect="true"/>

  <!-- ======================= -->
  <!-- === Caster === -->
  <!-- ======================= -->

  <link name="caster">
    <visual>
      <origin xyz="0 0 0.0045" rpy="0 0 0"/>
      <geometry>
        <mesh filename="file://$(find tp1_robot)/meshes/caster_base.stl"/>
      </geometry>
      <material name="${caster_color}"/>
    </visual>
  </link>
  <joint name="caster_joint" type="fixed">
    <parent link="base_link"/>
    <child link="caster"/>
    <origin xyz="${caster_origin_xyz}" rpy="0 0 0"/>
  </joint>

  <link name="caster_wheel">
    <visual>
      <origin xyz="-0.015 0 -0.020" rpy="0 0 0"/>
      <geometry>
        <mesh filename="file://$(find tp1_robot)/meshes/caster_wheel.stl"/>
      </geometry>
      <material name="${caster_color}"/>
    </visual>
  </link>
  <joint name="caster_wheel_joint" type="continuous">
    <parent link="caster"/>
    <child link="caster_wheel"/>
    <origin xyz="0 0 -0.01" rpy="0 0 0"/>
    <axis xyz="0 0 1"/>
  </joint>

  <link name="caster_wheel_support">
    <visual>
      <origin xyz="0 0 0" rpy="0 0 0"/>
      <geometry>
        <mesh filename="file://$(find tp1_robot)/meshes/caster_wheel_support.stl"/>
      </geometry>
      <material name="${caster_color}"/>
    </visual>
  </link>
  <joint name="caster_support_joint" type="fixed">
    <parent link="caster_wheel"/>
    <child link="caster_wheel_support"/>
    <origin xyz="0 0 0" rpy="0 0 0"/>
  </joint>

  <!-- ======================= -->
  <!-- === Frame odométrico === -->
  <!-- ======================= -->

  <link name="odom"/>
  <joint name="odom_to_base_link" type="fixed">
    <parent link="odom"/>
    <child link="base_link"/>
    <origin xyz="0 0 0" rpy="0 0 0"/>
  </joint>

  <!-- ======================= -->
  <!-- === ros2_control === -->
  <!-- ======================= -->

  <ros2_control name="DiffbotSystemHardware" type="system">
    <hardware>
      <plugin>gz_ros2_control/DefaultSystem</plugin>
    </hardware>

    <joint name="left_wheel_joint">
      <command_interface name="velocity"/>
      <state_interface name="position"/>
      <state_interface name="velocity"/>
    </joint>

    <joint name="right_wheel_joint">
      <command_interface name="velocity"/>
      <state_interface name="position"/>
      <state_interface name="velocity"/>
    </joint>

    <joint name="caster_wheel_joint">
      <state_interface name="position"/>
      <state_interface name="velocity"/>
    </joint>
  </ros2_control>

  <!-- ============================ -->
  <!-- === Plugin para Gazebo ==== -->
  <!-- ============================ -->

  <gazebo>
    <plugin name="gz_ros2_control" filename="libgz_ros2_control.so">
      <ros2_control_parameters>$(find tp1_robot)/config/diffbot_controllers.yaml</ros2_control_parameters>
    </plugin>
  </gazebo>

</robot>