<?xml version="1.0"?>
<robot name="diffbot" xmlns:xacro="http://www.ros.org/wiki/xacro">

  <!-- Propiedades -->
  <xacro:property name="chassis_mass" value="0.8"/>
  <xacro:property name="wheel_radius" value="0.035"/>
  <xacro:property name="wheel_width" value="0.025"/>
  <xacro:property name="wheel_separation" value="0.16"/>

  <!-- Includes -->
  <xacro:include filename="$(find tp1_robot)/urdf/inertial_macros.xacro"/>
  <xacro:include filename="$(find tp1_robot)/urdf/motor.xacro"/>

  <!-- Chasis -->
  <link name="base_link">
    <visual>
      <origin xyz="0 0 0" rpy="0 0 0"/>
      <geometry>
        <mesh filename="file://$(find tp1_robot)/meshes/chassis.stl"/>
      </geometry>
    </visual>
    <collision>
      <origin xyz="0 0 0" rpy="0 0 0"/>
      <geometry>
        <box size="0.195 0.1 0.05"/>
      </geometry>
    </collision>
    <xacro:inertial_box mass="${chassis_mass}" x="0.195" y="0.1" z="0.05">
      <origin xyz="0 0 0" rpy="0 0 0"/>
    </xacro:inertial_box>
  </link>

  <!-- Ruedas -->
  <xacro:macro name="wheel" params="prefix xyz axis">
    <link name="${prefix}_wheel">
      <visual>
        <origin xyz="0 0 0" rpy="1.5708 0 0"/>
        <geometry>
          <cylinder radius="${wheel_radius}" length="${wheel_width}"/>
        </geometry>
      </visual>
      <collision>
        <origin xyz="0 0 0" rpy="1.5708 0 0"/>
        <geometry>
          <cylinder radius="${wheel_radius}" length="${wheel_width}"/>
        </geometry>
      </collision>
    </link>

    <joint name="${prefix}_wheel_joint" type="continuous">
      <origin xyz="${xyz}" rpy="0 0 0"/>
      <parent link="base_link"/>
      <child link="${prefix}_wheel"/>
      <axis xyz="${axis}"/>
    </joint>
  </xacro:macro>

  <!-- Instancias de ruedas -->
  <xacro:wheel prefix="left"  xyz="0.0175  0.065 -0.0175" axis="0 1 0"/>
  <xacro:wheel prefix="right" xyz="0.0175 -0.065 -0.0175" axis="0 1 0"/>

  <!-- Motores -->
  <xacro:motor prefix="left" chassis_width="0.1" reflect="false"/>
  <xacro:motor prefix="right" chassis_width="0.1" reflect="true"/>

  <!-- Caster Base -->
  <link name="caster_base">
    <visual>
      <origin xyz="0.08 0 0" rpy="0 0 0"/>
      <geometry>
        <mesh filename="file://$(find tp1_robot)/meshes/caster_base.stl"/>
      </geometry>
    </visual>
  </link>
  <joint name="caster_base_joint" type="fixed">
    <parent link="base_link"/>
    <child link="caster_base"/>
    <origin xyz="0.08 0 -0.025" rpy="0 0 0"/>
  </joint>

  <!-- Caster Wheel -->
  <link name="caster_wheel">
    <visual>
      <origin xyz="0 0 -0.01" rpy="0 0 0"/>
      <geometry>
        <mesh filename="file://$(find tp1_robot)/meshes/caster_wheel.stl"/>
      </geometry>
    </visual>
  </link>
  <joint name="caster_wheel_joint" type="fixed">
    <parent link="caster_base"/>
    <child link="caster_wheel"/>
    <origin xyz="0 0 -0.01" rpy="0 0 0"/>
  </joint>

  <!-- Caster Wheel Support -->
  <link name="caster_wheel_support">
    <visual>
      <origin xyz="0 0 0" rpy="0 0 0"/>
      <geometry>
        <mesh filename="file://$(find tp1_robot)/meshes/caster_wheel_support.stl"/>
      </geometry>
    </visual>
  </link>
  <joint name="caster_support_joint" type="fixed">
    <parent link="caster_wheel"/>
    <child link="caster_wheel_support"/>
    <origin xyz="0 0 0" rpy="0 0 0"/>
  </joint>

  <!-- Transformación odom -->
  <link name="odom"/>
  <joint name="odom_to_base_link" type="fixed">
    <parent link="odom"/>
    <child link="base_link"/>
    <origin xyz="0 0 0" rpy="0 0 0"/>
  </joint>

  <!-- Plugin Gazebo -->
  <gazebo>
    <plugin name="gazebo_ros_control" filename="libgazebo_ros_diff_drive.so">
      <ros><namespace>/diffbot</namespace></ros>
      <wheel_separation>${wheel_separation}</wheel_separation>
      <wheel_diameter>0.07</wheel_diameter>
      <left_joint>left_wheel_joint</left_joint>
      <right_joint>right_wheel_joint</right_joint>
    </plugin>
  </gazebo>

  <!-- ROS2 Control -->
  <ros2_control name="diffbot_controller" type="system">
    <hardware>
      <plugin>gazebo_ros2_control/RobotHWSim</plugin>
    </hardware>
    <joint name="left_wheel_joint">
      <command_interface name="velocity"/>
      <state_interface name="position"/>
      <state_interface name="velocity"/>
    </joint>
    <joint name="right_wheel_joint">
      <command_interface name="velocity"/>
      <state_interface name="position"/>
      <state_interface name="velocity"/>
    </joint>
  </ros2_control>

</robot>
